<?xml version="1.0" encoding="utf-8"?>
<!-- =================================================================================== -->
<!-- |    This document was autogenerated by xacro from vawt_1.xacro                   | -->
<!-- |    EDITING THIS FILE BY HAND IS NOT RECOMMENDED                                 | -->
<!-- =================================================================================== -->
<!-- Revolute-Revolute Manipulator -->
<robot name="vawt_1">
  <!-- arbitrary value for mass -->
  <!-- ros_control plugin -->
  <gazebo>
    <plugin filename="libgazebo_ros_control.so" name="gazebo_ros_control">
      <robotNamespace>/vawt_1</robotNamespace>
      <robotSimType>gazebo_ros_control/DefaultRobotHWSim</robotSimType>
    </plugin>
  </gazebo>
  <!-- base link -->
  <gazebo reference="base">
    <material>Gazebo/Orange</material>
  </gazebo>
  <!-- blade_1-->
  <gazebo reference="blade_1">
    <mu1>0.2</mu1>
    <mu2>0.2</mu2>
    <material>Gazebo/Red</material>
  </gazebo>
  <!-- blade_2-->
  <gazebo reference="blade_2">
    <mu1>0.2</mu1>
    <mu2>0.2</mu2>
    <material>Gazebo/Black</material>
  </gazebo>
  <!-- main_shaft -->
  <gazebo reference="main_shaft">
    <mu1>0.2</mu1>
    <mu2>0.2</mu2>
    <material>Gazebo/Blue</material>
  </gazebo>
  <material name="black">
    <color rgba="0.0 0.0 0.0 1.0"/>
  </material>
  <material name="blue">
    <color rgba="0.0 0.0 0.8 1.0"/>
  </material>
  <material name="green">
    <color rgba="0.0 0.8 0.0 1.0"/>
  </material>
  <material name="grey">
    <color rgba="0.2 0.2 0.2 1.0"/>
  </material>
  <material name="orange">
    <color rgba="1.0 0.423529411765 0.0392156862745 1.0"/>
  </material>
  <material name="brown">
    <color rgba="0.870588235294 0.811764705882 0.764705882353 1.0"/>
  </material>
  <material name="red">
    <color rgba="0.8 0.0 0.0 1.0"/>
  </material>
  <material name="white">
    <color rgba="1.0 1.0 1.0 1.0"/>
  </material>
  <!-- Used for fixing robot to Gazebo 'base_link' -->
  <link name="world"/>
  <joint name="fixed" type="fixed">
    <parent link="world"/>
    <child link="base"/>
  </joint>
  <!-- z -->
  <link name="base">
    <collision>
      <origin rpy="0 0 0" xyz="0 0 0.05"/>
      <geometry>
        <box size="1 1 0.1"/>
      </geometry>
    </collision>
    <visual>
      <origin rpy="0 0 0" xyz="0 0 0.05"/>
      <geometry>
        <box size="1 1 0.1"/>
      </geometry>
      <material name="orange"/>
    </visual>
    <inertial>
      <origin rpy="0 0 0" xyz="0 0 0.05"/>
      <mass value="1"/>
      <inertia ixx="0.0841666666667" ixy="0.0" ixz="0.0" iyy="0.0841666666667" iyz="0.0" izz="0.166666666667"/>
    </inertial>
  </link>
  <joint name="main_shaft_joint" type="continuous">
    <parent link="base"/>
    <child link="main_shaft"/>
    <origin xyz="0 0 0.11"/>
    <axis xyz="0 0 1"/>
    <dynamics damping="0" friction="1"/>
  </joint>
  <!-- l  -->
  <link name="main_shaft">
    <collision>
      <origin rpy="0 0 0" xyz="0 0 1.0"/>
      <geometry>
        <cylinder length="2" radius="0.1"/>
      </geometry>
    </collision>
    <visual>
      <origin rpy="0 0 0" xyz="0 0 1.0"/>
      <geometry>
        <cylinder length="2" radius="0.1"/>
      </geometry>
      <material name="blue"/>
    </visual>
    <inertial>
      <origin rpy="0 0 0" xyz="0 0 1.0"/>
      <mass value="1"/>
      <inertia ixx="0.335833333333" ixy="0.0" ixz="0.0" iyy="0.335833333333" iyz="0.0" izz="0.005"/>
    </inertial>
  </link>
  <joint name="blade_1_bottom_strut_joint" type="fixed">
    <parent link="main_shaft"/>
    <child link="blade_1_bottom_strut"/>
    <origin rpy="0 0 0" xyz="0 0 0.666666666667"/>
  </joint>
  <link name="blade_1_bottom_strut">
    <collision>
      <origin rpy="0 1.57079632679 0" xyz="0.6 0 0"/>
      <geometry>
        <box size="0.05 0.1 1"/>
      </geometry>
    </collision>
    <visual>
      <origin rpy="0 1.57079632679 0" xyz="0.6 0 0"/>
      <geometry>
        <box size="0.05 0.1 1"/>
      </geometry>
      <material name="orange"/>
    </visual>
    <inertial>
      <origin rpy="0 1.57079632679 0" xyz="0.6 0 0"/>
      <mass value="1"/>
      <inertia ixx="0.0841666666667" ixy="0.0" ixz="0.0" iyy="0.0835416666667" iyz="0.0" izz="0.00104166666667"/>
    </inertial>
  </link>
  <joint name="blade_1_upper_strut_joint" type="fixed">
    <parent link="main_shaft"/>
    <child link="blade_1_upper_strut"/>
    <origin rpy="0 0 0" xyz="0 0 1.33333333333"/>
  </joint>
  <link name="blade_1_upper_strut">
    <collision>
      <origin rpy="0 1.57079632679 0" xyz="0.6 0 0"/>
      <geometry>
        <box size="0.05 0.1 1"/>
      </geometry>
    </collision>
    <visual>
      <origin rpy="0 1.57079632679 0" xyz="0.6 0 0"/>
      <geometry>
        <box size="0.05 0.1 1"/>
      </geometry>
      <material name="orange"/>
    </visual>
    <inertial>
      <origin rpy="0 1.57079632679 0" xyz="0.6 0 0"/>
      <mass value="1"/>
      <inertia ixx="0.0841666666667" ixy="0.0" ixz="0.0" iyy="0.0835416666667" iyz="0.0" izz="0.00104166666667"/>
    </inertial>
  </link>
  <joint name="blade_1_joint" type="revolute">
    <parent link="blade_1_bottom_strut"/>
    <child link="blade_1"/>
    <origin rpy="0 0 0" xyz="1.1 0 0"/>
    <axis xyz="0 0 1"/>
    <limit effort="300" lower="-3.14" upper="3.14" velocity="0.1"/>
  </joint>
  <transmission name="blade_1_transmission">
    <type>transmission_interface/SimpleTransmission</type>
    <joint name="blade_1_joint">
      <hardwareInterface>hardware_interface/EffortJointInterface</hardwareInterface>
    </joint>
    <actuator name="blade_1_motor">
      <hardwareInterface>EffortJointInterface</hardwareInterface>
      <mechanicalReduction>1</mechanicalReduction>
    </actuator>
  </transmission>
  <link name="blade_1">
    <collision>
      <origin rpy="0 0 1.57079632679" xyz="0 0 0.333333333333"/>
      <geometry>
        <box size="0.2 0.01 2"/>
      </geometry>
    </collision>
    <visual>
      <origin rpy="0 0 1.57079632679" xyz="0 0 0.333333333333"/>
      <geometry>
        <box size="0.2 0.01 2"/>
      </geometry>
      <material name="green"/>
    </visual>
    <inertial>
      <origin rpy="0 0 1.57079632679" xyz="0 0 0.333333333333"/>
      <mass value="1"/>
      <inertia ixx="0.333341666667" ixy="0.0" ixz="0.0" iyy="0.336666666667" iyz="0.0" izz="0.00334166666667"/>
    </inertial>
  </link>
  <joint name="blade_2_bottom_strut_joint" type="fixed">
    <parent link="main_shaft"/>
    <child link="blade_2_bottom_strut"/>
    <origin rpy="0 0 3.14159265359" xyz="0 0 0.666666666667"/>
  </joint>
  <link name="blade_2_bottom_strut">
    <collision>
      <origin rpy="0 1.57079632679 0" xyz="0.6 0 0"/>
      <geometry>
        <box size="0.05 0.1 1"/>
      </geometry>
    </collision>
    <visual>
      <origin rpy="0 1.57079632679 0" xyz="0.6 0 0"/>
      <geometry>
        <box size="0.05 0.1 1"/>
      </geometry>
      <material name="orange"/>
    </visual>
    <inertial>
      <origin rpy="0 1.57079632679 0" xyz="0.6 0 0"/>
      <mass value="1"/>
      <inertia ixx="0.0841666666667" ixy="0.0" ixz="0.0" iyy="0.0835416666667" iyz="0.0" izz="0.00104166666667"/>
    </inertial>
  </link>
  <joint name="blade_2_upper_strut_joint" type="fixed">
    <parent link="main_shaft"/>
    <child link="blade_2_upper_strut"/>
    <origin rpy="0 0 3.14159265359" xyz="0 0 1.33333333333"/>
  </joint>
  <link name="blade_2_upper_strut">
    <collision>
      <origin rpy="0 1.57079632679 0" xyz="0.6 0 0"/>
      <geometry>
        <box size="0.05 0.1 1"/>
      </geometry>
    </collision>
    <visual>
      <origin rpy="0 1.57079632679 0" xyz="0.6 0 0"/>
      <geometry>
        <box size="0.05 0.1 1"/>
      </geometry>
      <material name="orange"/>
    </visual>
    <inertial>
      <origin rpy="0 1.57079632679 0" xyz="0.6 0 0"/>
      <mass value="1"/>
      <inertia ixx="0.0841666666667" ixy="0.0" ixz="0.0" iyy="0.0835416666667" iyz="0.0" izz="0.00104166666667"/>
    </inertial>
  </link>
  <joint name="blade_2_joint" type="revolute">
    <parent link="blade_2_bottom_strut"/>
    <child link="blade_2"/>
    <origin rpy="0 0 0" xyz="1.1 0 0"/>
    <axis xyz="0 0 1"/>
    <limit effort="300" lower="-3.14" upper="3.14" velocity="0.1"/>
  </joint>
  <transmission name="blade_2_transmission">
    <type>transmission_interface/SimpleTransmission</type>
    <joint name="blade_2_joint">
      <hardwareInterface>hardware_interface/EffortJointInterface</hardwareInterface>
    </joint>
    <actuator name="blade_2_motor">
      <hardwareInterface>EffortJointInterface</hardwareInterface>
      <mechanicalReduction>1</mechanicalReduction>
    </actuator>
  </transmission>
  <link name="blade_2">
    <collision>
      <origin rpy="0 0 1.57079632679" xyz="0 0 0.333333333333"/>
      <geometry>
        <box size="0.2 0.01 2"/>
      </geometry>
    </collision>
    <visual>
      <origin rpy="0 0 1.57079632679" xyz="0 0 0.333333333333"/>
      <geometry>
        <box size="0.2 0.01 2"/>
      </geometry>
      <material name="green"/>
    </visual>
    <inertial>
      <origin rpy="0 0 1.57079632679" xyz="0 0 0.333333333333"/>
      <mass value="1"/>
      <inertia ixx="0.333341666667" ixy="0.0" ixz="0.0" iyy="0.336666666667" iyz="0.0" izz="0.00334166666667"/>
    </inertial>
  </link>
</robot>

